<robot
  name="trx_robot">
  <link
    name="base_footprint" />
  <joint
    name="base_footprint_joint"
    type="fixed">
    <origin
      xyz="0 0 0.1249217"
      rpy="0 0 0" />
    <parent
      link="base_footprint" />
    <child
      link="base_link" />
    <axis
      xyz="0 0 0" />
  </joint>
  <link
    name="base_link">
    <inertial>
      <origin
        xyz="-0.0692440825092598 0.0182922624656937 0.237170529840157"
        rpy="0 0 0" />
      <mass
        value="30" />
        <inertia
          ixx="0.31639"
          ixy="-9.1727E-05"
          ixz="-0.093044"
          iyy="0.17997"
          iyz="5.3231E-05"
          izz="0.16693" />
        </inertial>
    <visual>
      <origin
        xyz="0 0 0"
        rpy="0 0 0" />
      <geometry>
        <mesh
          filename="package://mobilican_description/trx/meshes/base_link.STL" />
      </geometry>
      <material
        name="">
        <color
          rgba="0.792156862745098 0.819607843137255 0.933333333333333 1" />
      </material>
    </visual>
    <collision>
      <origin
        xyz="-0.085 0 0.099"
        rpy="0 0 0" />
      <geometry>
        <box size="0.505 0.49 0.30"/>
      </geometry>
    </collision>
  </link>
  <link
    name="wheel_front_left">
    <inertial>
      <origin
        xyz="-1.21644384353906E-05 5.02355698706047E-09 -9.95261350565096E-07"
        rpy="0 0 0" />
      <mass
        value="1.19468309242743" />
      <inertia
        ixx="7.74298617751514E-12"
        ixy="4.77668429431615E-13"
        ixz="-9.46351217357088E-11"
        iyy="1.16440692697894E-09"
        iyz="3.90815349771352E-14"
        izz="1.15666433532758E-09" />
    </inertial>
    <visual>
      <origin
        xyz="0 0 0"
        rpy="0 0 0" />
      <geometry>
        <mesh
          filename="package://mobilican_description/trx/meshes/wheel.STL" />
      </geometry>
      <material
        name="">
        <color
          rgba="0.792156862745098 0.819607843137255 0.933333333333333 1" />
      </material>
    </visual>
    <collision>
      <origin
        xyz="0 0 0"
        rpy="1.57079632679 0 0" />
      <geometry>
        <cylinder length="0.05" radius="0.1016"/>
      </geometry>
    </collision>
  </link>
  <joint
    name="wheel_front_left_joint"
    type="continuous">
    <origin
      xyz="0 0.161374439975416 -0.0234217078108803"
      rpy="0 0 0" />
    <parent
      link="base_link" />
    <child
      link="wheel_front_left" />
    <axis
      xyz="0 1 0" />
  </joint>
  <link
    name="wheel_front_right">
    <inertial>
      <origin
        xyz="-1.13586030646491E-05 4.63149307794453E-09 4.46980487417472E-06"
        rpy="0 0 0" />
      <mass
        value="1.19468304304187" />
      <inertia
        ixx="1.5617116656522E-10"
        ixy="4.11215238883151E-13"
        ixz="3.96859468487808E-10"
        iyy="1.16466450182379E-09"
        iyz="-1.61820240450466E-13"
        izz="1.00849367060624E-09" />
    </inertial>
    <visual>
      <origin
        xyz="0 0 0"
        rpy="0 0 0" />
      <geometry>
        <mesh
          filename="package://mobilican_description/trx/meshes/wheel.STL" />
      </geometry>
      <material
        name="">
        <color
          rgba="0.792156862745098 0.819607843137255 0.933333333333333 1" />
      </material>
    </visual>
    <collision>
      <origin
        xyz="0 0 0"
        rpy="1.57079632679 0 0" />
      <geometry>
        <cylinder length="0.05" radius="0.1016"/>
      </geometry>
    </collision>
  </link>
  <joint
    name="wheel_front_right_joint"
    type="continuous">
    <origin
      xyz="0 -0.162374439255704 -0.0236218050730315"
      rpy="0 0 0" />
    <parent
      link="base_link" />
    <child
      link="wheel_front_right" />
    <axis
      xyz="0 1 0" />
  </joint>
  <link
    name="wheel_rear_right" >
    <collision>
      <origin
        xyz="0 0 0"
        rpy="1.57079632679 0 0" />
      <geometry>
        <cylinder length="0.05" radius="0.05"/>
      </geometry>
    </collision>
  </link>
  <joint
    name="wheel_rear_right_joint"
    type="fixed">
    <origin
      xyz="-0.271003476510462 -0.162949999975416 -0.0745000000000001"
      rpy="0 0 0" />
    <parent
      link="base_link" />
    <child
      link="wheel_rear_right" />
    <axis
      xyz="0 0 0" />
  </joint>
  <link
    name="wheel_rear_left" >
    <collision>
      <origin
        xyz="0 0 0"
        rpy="1.57079632679 0 0" />
      <geometry>
        <cylinder length="0.05" radius="0.05"/>
      </geometry>
    </collision>
  </link>
  <joint
    name="wheel_rear_left_joint"
    type="fixed">
    <origin
      xyz="-0.271003476510462 0.163449999975415 -0.074499999999999"
      rpy="0 0 0" />
    <parent
      link="base_link" />
    <child
      link="wheel_rear_left" />
    <axis
      xyz="0 0 0" />
  </joint>
  <link
    name="top_cam" />
  <joint
    name="top_cam_joint"
    type="fixed">
    <origin
      xyz="-0.172253476510556 0.041150000000327 1.637"
      rpy="0 0 -1.5707963267949" />
    <parent
      link="base_link" />
    <child
      link="top_cam" />
    <axis
      xyz="0 0 0" />
  </joint>
  <link
    name="middle_cam" />
  <joint
    name="middle_cam_joint"
    type="fixed">
    <origin
      xyz="-0.172253476510554 0.0411500000003268 1.025"
      rpy="1.5707963267949 0 -1.5707963267949" />
    <parent
      link="base_link" />
    <child
      link="middle_cam" />
    <axis
      xyz="0 0 0" />
  </joint>
  <link
    name="bottom_cam" />
  <joint
    name="bottom_cam_joint"
    type="fixed">
    <origin
      xyz="-0.172253476510552 0.0411500000003266 0.413"
      rpy="1.5707963267949 0 -1.5707963267949" />
    <parent
      link="base_link" />
    <child
      link="bottom_cam" />
    <axis
      xyz="0 0 0" />
  </joint>
  <link
    name="urf_right" />
  <joint
    name="urf_right_joint"
    type="fixed">
    <origin
      xyz="-0.144341676509997 -0.256667800000231 0.133209200000233"
      rpy="0 1.35106767363053E-15 -1.5707963267949" />
    <parent
      link="base_link" />
    <child
      link="urf_right" />
    <axis
      xyz="0 0 0" />
  </joint>
  <link
    name="urf_front" />
  <joint
    name="urf_front_joint"
    type="fixed">
    <origin
      xyz="0.17884165009831 -0.00158789542081382 0.133211187882727"
      rpy="0 0 0" />
    <parent
      link="base_link" />
    <child
      link="urf_front" />
    <axis
      xyz="0 0 0" />
  </joint>
  <link
    name="urf_left" />
  <joint
    name="urf_left_joint"
    type="fixed">
    <origin
      xyz="-0.141165581089183 0.261667800000231 0.133211187882727"
      rpy="0 2.14569775825973E-15 1.5707963267949" />
    <parent
      link="base_link" />
    <child
      link="urf_left" />
    <axis
      xyz="0 0 0" />
  </joint>
  <link
    name="depth_cam" />
  <joint
    name="depth_cam_joint"
    type="fixed">
    <origin
      xyz="0.157059201989492 0.00610692694567507 0.230098853117374"
      rpy="0 0 0" />
    <parent
      link="base_link" />
    <child
      link="depth_cam" />
    <axis
      xyz="0 0 0" />
  </joint>
  <link
    name="lidar" />
  <joint
    name="lidar_joint"
    type="fixed">
    <origin
      xyz="0.0892465234900025 -0.00125000000023005 0.328054161265183"
      rpy="-1.5707963267949 0 0" />
    <parent
      link="base_link" />
    <child
      link="lidar" />
    <axis
      xyz="0 0 0" />
  </joint>

</robot>
